[2024-01-29T18:05:26.163+0000] {taskinstance.py:1159} INFO - Dependencies all met for dep_context=non-requeueable deps ti=<TaskInstance: Dag_ses_burnoye_forecast.weather_to_bd scheduled__2024-01-28T09:30:00+00:00 [queued]>
[2024-01-29T18:05:26.178+0000] {taskinstance.py:1159} INFO - Dependencies all met for dep_context=requeueable deps ti=<TaskInstance: Dag_ses_burnoye_forecast.weather_to_bd scheduled__2024-01-28T09:30:00+00:00 [queued]>
[2024-01-29T18:05:26.179+0000] {taskinstance.py:1361} INFO - Starting attempt 1 of 10
[2024-01-29T18:05:26.196+0000] {taskinstance.py:1382} INFO - Executing <Task(PythonOperator): weather_to_bd> on 2024-01-28 09:30:00+00:00
[2024-01-29T18:05:26.204+0000] {standard_task_runner.py:57} INFO - Started process 109 to run task
[2024-01-29T18:05:26.208+0000] {standard_task_runner.py:84} INFO - Running: ['***', 'tasks', 'run', 'Dag_ses_burnoye_forecast', 'weather_to_bd', 'scheduled__2024-01-28T09:30:00+00:00', '--job-id', '5', '--raw', '--subdir', 'DAGS_FOLDER/dag_ses_burnoye.py', '--cfg-path', '/tmp/tmpltw6299b']
[2024-01-29T18:05:26.211+0000] {standard_task_runner.py:85} INFO - Job 5: Subtask weather_to_bd
[2024-01-29T18:05:26.265+0000] {task_command.py:416} INFO - Running <TaskInstance: Dag_ses_burnoye_forecast.weather_to_bd scheduled__2024-01-28T09:30:00+00:00 [running]> on host 88cd4f1bae89
[2024-01-29T18:05:26.363+0000] {taskinstance.py:1662} INFO - Exporting env vars: AIRFLOW_CTX_DAG_OWNER='***' AIRFLOW_CTX_DAG_ID='Dag_ses_burnoye_forecast' AIRFLOW_CTX_TASK_ID='weather_to_bd' AIRFLOW_CTX_EXECUTION_DATE='2024-01-28T09:30:00+00:00' AIRFLOW_CTX_TRY_NUMBER='1' AIRFLOW_CTX_DAG_RUN_ID='scheduled__2024-01-28T09:30:00+00:00'
[2024-01-29T18:05:28.412+0000] {taskinstance.py:1937} ERROR - Task failed with exception
Traceback (most recent call last):
  File "/home/airflow/.local/lib/python3.8/site-packages/urllib3/connection.py", line 174, in _new_conn
    conn = connection.create_connection(
  File "/home/airflow/.local/lib/python3.8/site-packages/urllib3/util/connection.py", line 95, in create_connection
    raise err
  File "/home/airflow/.local/lib/python3.8/site-packages/urllib3/util/connection.py", line 85, in create_connection
    sock.connect(sa)
ConnectionRefusedError: [Errno 111] Connection refused

During handling of the above exception, another exception occurred:

Traceback (most recent call last):
  File "/home/airflow/.local/lib/python3.8/site-packages/urllib3/connectionpool.py", line 714, in urlopen
    httplib_response = self._make_request(
  File "/home/airflow/.local/lib/python3.8/site-packages/urllib3/connectionpool.py", line 415, in _make_request
    conn.request(method, url, **httplib_request_kw)
  File "/home/airflow/.local/lib/python3.8/site-packages/urllib3/connection.py", line 244, in request
    super(HTTPConnection, self).request(method, url, body=body, headers=headers)
  File "/usr/local/lib/python3.8/http/client.py", line 1256, in request
    self._send_request(method, url, body, headers, encode_chunked)
  File "/usr/local/lib/python3.8/http/client.py", line 1302, in _send_request
    self.endheaders(body, encode_chunked=encode_chunked)
  File "/usr/local/lib/python3.8/http/client.py", line 1251, in endheaders
    self._send_output(message_body, encode_chunked=encode_chunked)
  File "/usr/local/lib/python3.8/http/client.py", line 1011, in _send_output
    self.send(msg)
  File "/usr/local/lib/python3.8/http/client.py", line 951, in send
    self.connect()
  File "/home/airflow/.local/lib/python3.8/site-packages/urllib3/connection.py", line 205, in connect
    conn = self._new_conn()
  File "/home/airflow/.local/lib/python3.8/site-packages/urllib3/connection.py", line 186, in _new_conn
    raise NewConnectionError(
urllib3.exceptions.NewConnectionError: <urllib3.connection.HTTPConnection object at 0x7f102dd77d30>: Failed to establish a new connection: [Errno 111] Connection refused

During handling of the above exception, another exception occurred:

Traceback (most recent call last):
  File "/home/airflow/.local/lib/python3.8/site-packages/requests/adapters.py", line 486, in send
    resp = conn.urlopen(
  File "/home/airflow/.local/lib/python3.8/site-packages/urllib3/connectionpool.py", line 798, in urlopen
    retries = retries.increment(
  File "/home/airflow/.local/lib/python3.8/site-packages/urllib3/util/retry.py", line 592, in increment
    raise MaxRetryError(_pool, url, error or ResponseError(cause))
urllib3.exceptions.MaxRetryError: HTTPConnectionPool(host='192.168.252.84', port=3225): Max retries exceeded with url: /weather_to_bd/ (Caused by NewConnectionError('<urllib3.connection.HTTPConnection object at 0x7f102dd77d30>: Failed to establish a new connection: [Errno 111] Connection refused'))

During handling of the above exception, another exception occurred:

Traceback (most recent call last):
  File "/home/airflow/.local/lib/python3.8/site-packages/airflow/operators/python.py", line 192, in execute
    return_value = self.execute_callable()
  File "/home/airflow/.local/lib/python3.8/site-packages/airflow/operators/python.py", line 209, in execute_callable
    return self.python_callable(*self.op_args, **self.op_kwargs)
  File "/opt/airflow/dags/dag_ses_burnoye.py", line 24, in weather_to_bd
    r = requests.post("http://192.168.252.84:3225/weather_to_bd/", json = {'gtp_code': gtp_code})
  File "/home/airflow/.local/lib/python3.8/site-packages/requests/api.py", line 115, in post
    return request("post", url, data=data, json=json, **kwargs)
  File "/home/airflow/.local/lib/python3.8/site-packages/requests/api.py", line 59, in request
    return session.request(method=method, url=url, **kwargs)
  File "/home/airflow/.local/lib/python3.8/site-packages/requests/sessions.py", line 589, in request
    resp = self.send(prep, **send_kwargs)
  File "/home/airflow/.local/lib/python3.8/site-packages/requests/sessions.py", line 703, in send
    r = adapter.send(request, **kwargs)
  File "/home/airflow/.local/lib/python3.8/site-packages/requests/adapters.py", line 519, in send
    raise ConnectionError(e, request=request)
requests.exceptions.ConnectionError: HTTPConnectionPool(host='192.168.252.84', port=3225): Max retries exceeded with url: /weather_to_bd/ (Caused by NewConnectionError('<urllib3.connection.HTTPConnection object at 0x7f102dd77d30>: Failed to establish a new connection: [Errno 111] Connection refused'))
[2024-01-29T18:05:28.431+0000] {taskinstance.py:1400} INFO - Marking task as UP_FOR_RETRY. dag_id=Dag_ses_burnoye_forecast, task_id=weather_to_bd, execution_date=20240128T093000, start_date=20240129T180526, end_date=20240129T180528
[2024-01-29T18:05:28.450+0000] {standard_task_runner.py:104} ERROR - Failed to execute job 5 for task weather_to_bd (HTTPConnectionPool(host='192.168.252.84', port=3225): Max retries exceeded with url: /weather_to_bd/ (Caused by NewConnectionError('<urllib3.connection.HTTPConnection object at 0x7f102dd77d30>: Failed to establish a new connection: [Errno 111] Connection refused')); 109)
[2024-01-29T18:05:28.469+0000] {local_task_job_runner.py:228} INFO - Task exited with return code 1
[2024-01-29T18:05:28.509+0000] {taskinstance.py:2778} INFO - 0 downstream tasks scheduled from follow-on schedule check
